Workbook
Name BalanceCheck: Model!$D$155:$AA$155

Sheet Cover
M7: LinkedIn: linkedin.com/in/valeriia-evtushenko-51110a304
C9: Financial Model – Multi‑Segment F&B Business
M19: Model Checks
C21: Table of Contents | M21: Balance Sheet Unbalanced | Q21: =IF(ROUND(SUM(BalanceCheck), 2) =0,0,1) -> 0
C23: Outputs
C24: Inputs
C25: Model
T26: Do Not
C27: Model Circularity | T27: Delete
C29: Model Circularity | F29: 1 | T29: Circularity
T30: On
T31: Off
C33: © 2026 Valeriia Evtushenko
C34: All rights reserved
C35: Fictional case study, created for portfolio demonstration purposes.
C36: All data is synthetic and not based on any real company.

Sheet Outputs
B2: Outputs
I4: All figures in CAD thousands unless stated
B5: Driver Switch | D5: =Model!D4 -> 1
B8: Historical Context — Pre-Credit Facility Period (2019–2023)
I10: 2019 | J10: 2020 | K10: 2021 | L10: 2022 | M10: 2023 | N10: 2024
B12: Revenue | I12: 8000 | J12: 9200 | K12: 10500 | L12: 11900 | M12: =SUM(Model!D14:O14) -> 13060.4 | N12: =SUM(Model!P14:AA14) -> 12210.45
B13: Expenses | I13: 7600 | J13: 9500 | K13: 11800 | L13: 16000 | M13: =-(SUM(Model!D20:O20)+SUM(Model!D15:O15)) -> 22104.24 | N13: =-(SUM(Model!P20:AA20)+SUM(Model!P15:AA15)) -> 24798.27
B14: Net Income | I14: =I12-I13 -> 400 | J14: =J12-J13 -> -300 | K14: =K12-K13 -> -1300 | L14: =L12-L13 -> -4100 | M14: =SUM(Model!D28:O28)-M15 -> -10681.515 | N14: =SUM(Model!P28:AA28)-N15 -> -15880.69
B15: Government Grants | I15: 800 | J15: 900 | K15: 1000 | L15: 1100 | M15: =Inputs!D19 -> 1800 | N15: =Inputs!E19 -> 1200
B20: Revenue vs. Total Expenses | J20: Total Net Income vs. Government Grants
B39: Historical analysis (2019–2022) shows that the company was unprofitable every year before the revolver was introduced. Grants temporarily covered the gap, but by 2023 the shortfall exceeded available funding, forcing the company to rely on debt.
B42: P&L and Cash Flow Waterfall Bridges
I44: 2024 | O44: 2024
B46: Revenue | I46: =SUM(Model!$P$14:$AA$14) -> 12210.45 | K46: Net Income | O46: =SUM(Model!P28:AA28) -> -14680.69
B47: COGS | I47: =SUM(Model!$P$15:$AA$15) -> -7326.27 | K47: Depreciation & Amortization | O47: =-SUM(Model!P23:AA23) -> 500
B48: Operation Expenses | I48: =SUM(Model!$P$20:$AA$20) -> -17472 | K48: Capital Expenditures | O48: =-SUM(Model!$P$104:$AA$104) -> 610.5225
B49: EBITDA | I49: =SUM(I46:I48) -> -12587.82 | K49: Change in Net Working Capital | O49: =SUM(Model!$P$98:$AA$98)+SUM(Model!$P$99:$AA$99)+SUM(Model!$P$100:$AA$100) -> 13.822603
B50: Depreciation & Amortization | I50: =SUM(Model!P23:AA23) -> -500 | K50: Government Grants | O50: =SUM(Model!$P$27:$AA$27) -> 1200
B51: EBIT | I51: =SUM(I49:I50) -> -13087.82 | K51: Revolver Draw (net) | O51: =SUM(Model!P111:AA111) -> 9012.2078
B52: Interest | I52: =SUM(Model!P26:AA26) -> -2792.8698 | K52: Term Loan Principal Payment | O52: =-SUM(Model!P110:AA110) -> 941.09826
B53: Net Income | I53: =SUM(I51:I52) -> -15880.69 | K53: Net Change in Cash | O53: =$O$46+$O$47-$O$48+$O$49+$O$50+$O$51-$O$52 -> -5506.2802
B57: 2024 P&L Waterfall Bridge | L57: 2024 Cash Flow Waterfall Bridge
B80: Operating expenses and interest now exceed total revenue, driving a deeper structural deficit than previously modeled — the business does not generate enough cash from operations to sustain itself.
B83: Cash flow analysis
D85: =Model!D8 -> 44927 | E85: =Model!E8 -> 44958 | F85: =Model!F8 -> 44986 | G85: =Model!G8 -> 45017 | H85: =Model!H8 -> 45047 | I85: =Model!I8 -> 45078 | J85: =Model!J8 -> 45108 | K85: =Model!K8 -> 45139 | ... AA85: =Model!AA8 -> 45627
B87: Ending Cash | D87: 500 | E87: =Model!E117 -> 500 | F87: =Model!F117 -> 500 | G87: =Model!G117 -> 500 | H87: =Model!H117 -> 500 | I87: =Model!I117 -> 500 | J87: =Model!J117 -> 500 | K87: =Model!K117 -> 500 | L87: =Model!L117 -> 500 | ... AA87: =Model!AA117 -> -6206.2802
B88: Revolver Balance | D88: =Model!D201 -> 1748.7363 | E88: =Model!E201 -> 2471.6505 | F88: =Model!F201 -> 3215.8547 | G88: =Model!G201 -> 3983.3489 | H88: =Model!H201 -> 4774.1331 | I88: =Model!I201 -> 5588.2073 | J88: =Model!J201 -> 6425.5715 | K88: =Model!K201 -> 7286.2258 | ... AA88: =Model!AA201 -> 20000
B89: Minimum Cash | D89: 500 | E89: 500 | F89: 500 | G89: 500 | H89: 500 | I89: 500 | J89: 500 | K89: 500 | L89: 500 | M89: 500 | N89: 500 | O89: 500 | P89: 500 | Q89: 500 | R89: 500 | S89: 500 | T89: 500 | U89: 500 | V89: 500 | W89: 500 | X89: 500 | Y89: 500 | Z89: 500 | AA89: 500
B113: The revolver reaches its limit of 20,000 in August 2024 — four months earlier than initially modeled. From that point, cash covenant breaches occur immediately, as the company has no remaining capacity to draw on the revolver to cover the shortfall.
B117: Debt / EBITDA (Leverage Ratio)
D119: =Model!D8 -> 44927 | E119: =Model!E8 -> 44958 | F119: =Model!F8 -> 44986 | G119: =Model!G8 -> 45017 | H119: =Model!H8 -> 45047 | I119: =Model!I8 -> 45078 | J119: =Model!J8 -> 45108 | K119: =Model!K8 -> 45139 | ... AA119: =Model!AA8 -> 45627
B121: Total Debt | D121: =Model!D142+Model!D139 -> 6676.8927 | E121: =Model!E142+Model!E139 -> 7327.6031 | F121: =Model!F142+Model!F139 -> 7999.2417 | G121: =Model!G142+Model!G139 -> 8693.8065 | H121: =Model!H142+Model!H139 -> 9411.2958 | I121: =Model!I142+Model!I139 -> 10151.708 | J121: =Model!J142+Model!J139 -> 10915.04 | K121: =Model!K142+Model!K139 -> 11701.292 | ... AA121: =Model!AA142+Model!AA139 -> 23172.609
B122: Annualized EBITDA | D122: =Model!D21*12 -> -8218.2 | E122: =Model!E21*12 -> -8365.32 | F122: =Model!F21*12 -> -8512.44 | G122: =Model!G21*12 -> -8659.56 | H122: =Model!H21*12 -> -8806.68 | I122: =Model!I21*12 -> -8953.8 | J122: =Model!J21*12 -> -9100.92 | K122: =Model!K21*12 -> -9248.04 | ... AA122: =Model!AA21*12 -> -14411.28
B123: Leverage Ratio | D123: =D121/D122 -> -0.81245195 | E123: =E121/E122 -> -0.87595013 | F123: =F121/F122 -> -0.93971196 | G123: =G121/G122 -> -1.0039548 | H123: =H121/H122 -> -1.0686542 | I123: =I121/I122 -> -1.1337876 | J123: =J121/J122 -> -1.1993337 | K123: =K121/K122 -> -1.2652726 | ... AA123: =AA121/AA122 -> -1.6079494
B142: Sensitivity Analysis
B144: NPV | E144: =XNPV(F144,Model!$D$107:$AA$107,Model!$D$8:$AA$8) -> -21292.396 | F144: =ROUNDDOWN(Model!E248,3) -> 0.111
B145: IRR | E145: =IFERROR(XIRR(Model!$D$107:$AA$107,Model!$D$8:$AA$8),"na") -> na
B146: Cash Runway | E146: =Model!$AA$117/(-Model!$D$107:$AA$107) -> -9.5376983
B147: Final Cash Balance | E147: =Model!$AA$117 -> -6206.2802
B148: Government Grants | E148: =Inputs!E19 -> 1200
...

Sheet Inputs
B2: Drivers | G2: Tax Assumption Note:
G3: No income tax is included in this model because the company generates negative Net Income in all periods (2023–2024), resulting in zero taxable income.
B4: All figures in CAD thousands unless stated | D4: 2023 | E4: 2024 | G4: For reference, the combined corporate tax rate in Nova Scotia is approximately 29% (15% federal + 14% provincial)
G5: In a real‑world model with positive earnings, I would add an income tax line between EBIT and Net Income and adjust the cash flow statement accordingly.
B6: Driver Switch | C6: =Model!D4 -> 1
B9: Revenue Growth | D9: =CHOOSE($C$6,D10,D11,D12) -> 0.03 | E9: =CHOOSE($C$6,E10,E11,E12) -> 0.015
B10: Base Case | D10: 0.03 | E10: 0.015
B11: Upside case | D11: 0.05 | E11: 0.035
B12: Downside Case | D12: 0.01 | E12: -0.01
B14: Expense Growth | D14: =CHOOSE($C$6,D15,D16,D17) -> 0.025 | E14: =CHOOSE($C$6,E15,E16,E17) -> 0.04
B15: Base Case | D15: 0.025 | E15: 0.04
B16: Upside case | D16: 0.015 | E16: 0.02
B17: Downside Case | D17: 0.04 | E17: 0.055
B19: Government Grants | D19: =CHOOSE($C$6,D20,D21,D22) -> 1800 | E19: =CHOOSE($C$6,E20,E21,E22) -> 1200
B20: Base Case | D20: =150*12 -> 1800 | E20: =100*12 -> 1200
B21: Upside case | D21: =200*12 -> 2400 | E21: =200*12 -> 2400
B22: Downside Case | D22: 0 | E22: 0
B25: Fixed Assumption
B27: Minimum Cash Covenant (Revolver Trigger) | C27: 500
B28: Annua lInterest Rate on Credit Line | C28: 0.15
B29: Revolver Limit | C29: 20000
B31: Long-Term Debt Assumption
B33: Loan Amount | C33: 5000
B34: Term | C34: 5
B35: Annual Interest Rate | C35: 0.06
B37: Useful life of Assets
B39: Useful life of Assets (years) | C39: 10
B41: Operation Working Capital Assumption
B43: AR days | C43: 15
B44: AP days | C44: 20
B45: Inventory days | C45: 10
B46: Capex % of Revenue | C46: 0.05
B48: Segment Revenue Mix
B50: Italian Restaurant | D50: =CHOOSE($C$6,D51,D52,D53) -> 0.25 | E50: =CHOOSE($C$6,E51,E52,E53) -> 0.22
B51: Base Case | D51: 0.25 | E51: 0.22
B52: Upside case | D52: 0.26 | E52: 0.24
B53: Downside Case | D53: 0.2 | E53: 0.18
B55: Japanese Restaurant | D55: =CHOOSE($C$6,D56,D57,D58) -> 0.2 | E55: =CHOOSE($C$6,E56,E57,E58) -> 0.17
B56: Base Case | D56: 0.2 | E56: 0.17
B57: Upside case | D57: 0.21 | E57: 0.2
...

Sheet Model
B2: Model
B4: =Inputs!B6 -> Driver Switch | D4: 1 | F4: All figures in CAD thousands unless stated
B8: Year 2023-2024 | D8: 44927 | E8: 44958 | F8: 44986 | G8: 45017 | H8: 45047 | I8: 45078 | J8: 45108 | K8: 45139 | L8: 45170 | M8: 45200 | N8: 45231 | O8: 45261 | P8: 45292 | Q8: 45323 | R8: 45352 | S8: 45383 | T8: 45413 | U8: 45444 | V8: 45474 | W8: 45505 | X8: 45536 | Y8: 45566 | Z8: 45597 | AA8: 45627
B10: Income Statement
B12: Revenue Growth | D12: =IF(YEAR(D$8)=2023,Inputs!$D$9,Inputs!$E$9) -> 0.03 | E12: =IF(YEAR(E$8)=2023,Inputs!$D$9,Inputs!$E$9) -> 0.03 | F12: =IF(YEAR(F$8)=2023,Inputs!$D$9,Inputs!$E$9) -> 0.03 | G12: =IF(YEAR(G$8)=2023,Inputs!$D$9,Inputs!$E$9) -> 0.03 | H12: =IF(YEAR(H$8)=2023,Inputs!$D$9,Inputs!$E$9) -> 0.03 | I12: =IF(YEAR(I$8)=2023,Inputs!$D$9,Inputs!$E$9) -> 0.03 | J12: =IF(YEAR(J$8)=2023,Inputs!$D$9,Inputs!$E$9) -> 0.03 | K12: =IF(YEAR(K$8)=2023,Inputs!$D$9,Inputs!$E$9) -> 0.03 | ... AA12: =IF(YEAR(AA$8)=2023,Inputs!$D$9,Inputs!$E$9) -> 0.015
B13: Base Revenue (generated) | D13: 950 | E13: 970 | F13: 990 | G13: 1010 | H13: 1030 | I13: 1050 | J13: 1070 | K13: 1090 | L13: 1110 | M13: 1130 | N13: 1150 | O13: 1130 | P13: 1110 | Q13: 1090 | R13: 1070 | S13: 1050 | T13: 1030 | U13: 1010 | V13: 990 | W13: 970 | X13: 950 | Y13: 930 | Z13: 920 | AA13: 910
B14: Revenue | D14: =D13*(D12+1) -> 978.5 | E14: =E13*(E12+1) -> 999.1 | F14: =F13*(F12+1) -> 1019.7 | G14: =G13*(G12+1) -> 1040.3 | H14: =H13*(H12+1) -> 1060.9 | I14: =I13*(I12+1) -> 1081.5 | J14: =J13*(J12+1) -> 1102.1 | K14: =K13*(K12+1) -> 1122.7 | ... AA14: =AA13*(AA12+1) -> 923.65
B15: COGS | D15: =-D14*60% -> -587.1 | E15: =-E14*60% -> -599.46 | F15: =-F14*60% -> -611.82 | G15: =-G14*60% -> -624.18 | H15: =-H14*60% -> -636.54 | I15: =-I14*60% -> -648.9 | J15: =-J14*60% -> -661.26 | K15: =-K14*60% -> -673.62 | ... AA15: =-AA14*60% -> -554.19
B16: Gross Profit | D16: =D14+D15 -> 391.4 | E16: =E14+E15 -> 399.64 | F16: =F14+F15 -> 407.88 | G16: =G14+G15 -> 416.12 | H16: =H14+H15 -> 424.36 | I16: =I14+I15 -> 432.6 | J16: =J14+J15 -> 440.84 | K16: =K14+K15 -> 449.08 | ... AA16: =AA14+AA15 -> 369.46
B18: Expenses Growth | D18: =IF(YEAR(D$8)=2023,Inputs!$D$14,Inputs!$E$14) -> 0.025 | E18: =IF(YEAR(E$8)=2023,Inputs!$D$14,Inputs!$E$14) -> 0.025 | F18: =IF(YEAR(F$8)=2023,Inputs!$D$14,Inputs!$E$14) -> 0.025 | G18: =IF(YEAR(G$8)=2023,Inputs!$D$14,Inputs!$E$14) -> 0.025 | H18: =IF(YEAR(H$8)=2023,Inputs!$D$14,Inputs!$E$14) -> 0.025 | I18: =IF(YEAR(I$8)=2023,Inputs!$D$14,Inputs!$E$14) -> 0.025 | J18: =IF(YEAR(J$8)=2023,Inputs!$D$14,Inputs!$E$14) -> 0.025 | K18: =IF(YEAR(K$8)=2023,Inputs!$D$14,Inputs!$E$14) -> 0.025 | ... AA18: =IF(YEAR(AA$8)=2023,Inputs!$D$14,Inputs!$E$14) -> 0.04
B19: Base Expenses (generated) | D19: -1050 | E19: -1070 | F19: -1090 | G19: -1110 | H19: -1130 | I19: -1150 | J19: -1170 | K19: -1190 | L19: -1210 | M19: -1230 | N19: -1250 | O19: -1270 | P19: -1290 | Q19: -1310 | R19: -1330 | S19: -1350 | T19: -1370 | U19: -1390 | V19: -1410 | W19: -1430 | X19: -1450 | Y19: -1470 | Z19: -1490 | AA19: -1510
B20: Operating Expenses | D20: =D19*(D18+1) -> -1076.25 | E20: =E19*(E18+1) -> -1096.75 | F20: =F19*(F18+1) -> -1117.25 | G20: =G19*(G18+1) -> -1137.75 | H20: =H19*(H18+1) -> -1158.25 | I20: =I19*(I18+1) -> -1178.75 | J20: =J19*(J18+1) -> -1199.25 | K20: =K19*(K18+1) -> -1219.75 | ... AA20: =AA19*(AA18+1) -> -1570.4
B21: EBITDA | D21: =D20+D16 -> -684.85 | E21: =E20+E16 -> -697.11 | F21: =F20+F16 -> -709.37 | G21: =G20+G16 -> -721.63 | H21: =H20+H16 -> -733.89 | I21: =I20+I16 -> -746.15 | J21: =J20+J16 -> -758.41 | K21: =K20+K16 -> -770.67 | ... AA21: =AA20+AA16 -> -1200.94
B23: Depreciation & Amortization | D23: =-Inputs!$C$33/(Inputs!$C$39*12) -> -41.666667 | E23: =-Inputs!$C$33/(Inputs!$C$39*12) -> -41.666667 | F23: =-Inputs!$C$33/(Inputs!$C$39*12) -> -41.666667 | G23: =-Inputs!$C$33/(Inputs!$C$39*12) -> -41.666667 | H23: =-Inputs!$C$33/(Inputs!$C$39*12) -> -41.666667 | I23: =-Inputs!$C$33/(Inputs!$C$39*12) -> -41.666667 | J23: =-Inputs!$C$33/(Inputs!$C$39*12) -> -41.666667 | K23: =-Inputs!$C$33/(Inputs!$C$39*12) -> -41.666667 | ... AA23: =-Inputs!$C$33/(Inputs!$C$39*12) -> -41.666667
B24: EBIT | D24: =SUM(D21:D23) -> -726.51667 | E24: =SUM(E21:E23) -> -738.77667 | F24: =SUM(F21:F23) -> -751.03667 | G24: =SUM(G21:G23) -> -763.29667 | H24: =SUM(H21:H23) -> -775.55667 | I24: =SUM(I21:I23) -> -787.81667 | J24: =SUM(J21:J23) -> -800.07667 | K24: =SUM(K21:K23) -> -812.33667 | ... AA24: =SUM(AA21:AA23) -> -1242.6067
B26: Interest | D26: =-D176-D206 -> -36.820391 | E26: =-E176-E206 -> -52.460273 | F26: =-F176-F206 -> -60.098349 | G26: =-G176-G206 -> -69.734611 | H26: =-H176-H206 -> -79.369051 | I26: =-I176-I206 -> -89.001657 | J26: =-J176-J206 -> -98.632422 | K26: =-K176-K206 -> -108.26134 | ... AA26: =-AA176-AA206 -> -266.06454
B27: Government Grants | D27: =IF(YEAR(D$8)=2023,Inputs!$D$19/12,Inputs!$E$19/12) -> 150 | E27: =IF(YEAR(E$8)=2023,Inputs!$D$19/12,Inputs!$E$19/12) -> 150 | F27: =IF(YEAR(F$8)=2023,Inputs!$D$19/12,Inputs!$E$19/12) -> 150 | G27: =IF(YEAR(G$8)=2023,Inputs!$D$19/12,Inputs!$E$19/12) -> 150 | H27: =IF(YEAR(H$8)=2023,Inputs!$D$19/12,Inputs!$E$19/12) -> 150 | I27: =IF(YEAR(I$8)=2023,Inputs!$D$19/12,Inputs!$E$19/12) -> 150 | J27: =IF(YEAR(J$8)=2023,Inputs!$D$19/12,Inputs!$E$19/12) -> 150 | K27: =IF(YEAR(K$8)=2023,Inputs!$D$19/12,Inputs!$E$19/12) -> 150 | ... AA27: =IF(YEAR(AA$8)=2023,Inputs!$D$19/12,Inputs!$E$19/12) -> 100
B28: Net Income | D28: =D24+D26+D27 -> -613.33706 | E28: =E24+E26+E27 -> -641.23694 | F28: =F24+F26+F27 -> -661.13502 | G28: =G24+G26+G27 -> -683.03128 | H28: =H24+H26+H27 -> -704.92572 | I28: =I24+I26+I27 -> -726.81832 | J28: =J24+J26+J27 -> -748.70909 | K28: =K24+K26+K27 -> -770.598 | ... AA28: =AA24+AA26+AA27 -> -1408.6712
B31: Segment P&L (breakdown by business units)
B33: Revenue by Segment
B35: Italian Restaurant | D35: =D$14*(IF(YEAR(D$8)=2023,Inputs!$D$50,Inputs!$E$50)) -> 244.625 | E35: =E$14*(IF(YEAR(E$8)=2023,Inputs!$D$50,Inputs!$E$50)) -> 249.775 | F35: =F$14*(IF(YEAR(F$8)=2023,Inputs!$D$50,Inputs!$E$50)) -> 254.925 | G35: =G$14*(IF(YEAR(G$8)=2023,Inputs!$D$50,Inputs!$E$50)) -> 260.075 | H35: =H$14*(IF(YEAR(H$8)=2023,Inputs!$D$50,Inputs!$E$50)) -> 265.225 | I35: =I$14*(IF(YEAR(I$8)=2023,Inputs!$D$50,Inputs!$E$50)) -> 270.375 | J35: =J$14*(IF(YEAR(J$8)=2023,Inputs!$D$50,Inputs!$E$50)) -> 275.525 | K35: =K$14*(IF(YEAR(K$8)=2023,Inputs!$D$50,Inputs!$E$50)) -> 280.675 | ... AA35: =AA$14*(IF(YEAR(AA$8)=2023,Inputs!$D$50,Inputs!$E$50)) -> 203.203
B36: Japanese Restaurant | D36: =D$14*(IF(YEAR(D$8)=2023,Inputs!$D$55,Inputs!$E$55)) -> 195.7 | E36: =E$14*(IF(YEAR(E$8)=2023,Inputs!$D$55,Inputs!$E$55)) -> 199.82 | F36: =F$14*(IF(YEAR(F$8)=2023,Inputs!$D$55,Inputs!$E$55)) -> 203.94 | G36: =G$14*(IF(YEAR(G$8)=2023,Inputs!$D$55,Inputs!$E$55)) -> 208.06 | H36: =H$14*(IF(YEAR(H$8)=2023,Inputs!$D$55,Inputs!$E$55)) -> 212.18 | I36: =I$14*(IF(YEAR(I$8)=2023,Inputs!$D$55,Inputs!$E$55)) -> 216.3 | J36: =J$14*(IF(YEAR(J$8)=2023,Inputs!$D$55,Inputs!$E$55)) -> 220.42 | K36: =K$14*(IF(YEAR(K$8)=2023,Inputs!$D$55,Inputs!$E$55)) -> 224.54 | ... AA36: =AA$14*(IF(YEAR(AA$8)=2023,Inputs!$D$55,Inputs!$E$55)) -> 157.0205
B37: Burger Joint | D37: =D$14*(IF(YEAR(D$8)=2023,Inputs!$D$60,Inputs!$E$60)) -> 176.13 | E37: =E$14*(IF(YEAR(E$8)=2023,Inputs!$D$60,Inputs!$E$60)) -> 179.838 | F37: =F$14*(IF(YEAR(F$8)=2023,Inputs!$D$60,Inputs!$E$60)) -> 183.546 | G37: =G$14*(IF(YEAR(G$8)=2023,Inputs!$D$60,Inputs!$E$60)) -> 187.254 | H37: =H$14*(IF(YEAR(H$8)=2023,Inputs!$D$60,Inputs!$E$60)) -> 190.962 | I37: =I$14*(IF(YEAR(I$8)=2023,Inputs!$D$60,Inputs!$E$60)) -> 194.67 | J37: =J$14*(IF(YEAR(J$8)=2023,Inputs!$D$60,Inputs!$E$60)) -> 198.378 | K37: =K$14*(IF(YEAR(K$8)=2023,Inputs!$D$60,Inputs!$E$60)) -> 202.086 | ... AA37: =AA$14*(IF(YEAR(AA$8)=2023,Inputs!$D$60,Inputs!$E$60)) -> 166.257
B38: Pizzeria | D38: =D$14*IF(YEAR(D$8)=2023,Inputs!$D$65,Inputs!$E$65) -> 146.775 | E38: =E$14*IF(YEAR(E$8)=2023,Inputs!$D$65,Inputs!$E$65) -> 149.865 | F38: =F$14*IF(YEAR(F$8)=2023,Inputs!$D$65,Inputs!$E$65) -> 152.955 | G38: =G$14*IF(YEAR(G$8)=2023,Inputs!$D$65,Inputs!$E$65) -> 156.045 | H38: =H$14*IF(YEAR(H$8)=2023,Inputs!$D$65,Inputs!$E$65) -> 159.135 | I38: =I$14*IF(YEAR(I$8)=2023,Inputs!$D$65,Inputs!$E$65) -> 162.225 | J38: =J$14*IF(YEAR(J$8)=2023,Inputs!$D$65,Inputs!$E$65) -> 165.315 | K38: =K$14*IF(YEAR(K$8)=2023,Inputs!$D$65,Inputs!$E$65) -> 168.405 | ... AA38: =AA$14*IF(YEAR(AA$8)=2023,Inputs!$D$65,Inputs!$E$65) -> 138.5475
B39: Beverage Brand | D39: =D$14*IF(YEAR(D$8)=2023,Inputs!$D$70,Inputs!$E$70) -> 117.42 | E39: =E$14*IF(YEAR(E$8)=2023,Inputs!$D$70,Inputs!$E$70) -> 119.892 | F39: =F$14*IF(YEAR(F$8)=2023,Inputs!$D$70,Inputs!$E$70) -> 122.364 | G39: =G$14*IF(YEAR(G$8)=2023,Inputs!$D$70,Inputs!$E$70) -> 124.836 | H39: =H$14*IF(YEAR(H$8)=2023,Inputs!$D$70,Inputs!$E$70) -> 127.308 | I39: =I$14*IF(YEAR(I$8)=2023,Inputs!$D$70,Inputs!$E$70) -> 129.78 | J39: =J$14*IF(YEAR(J$8)=2023,Inputs!$D$70,Inputs!$E$70) -> 132.252 | K39: =K$14*IF(YEAR(K$8)=2023,Inputs!$D$70,Inputs!$E$70) -> 134.724 | ... AA39: =AA$14*IF(YEAR(AA$8)=2023,Inputs!$D$70,Inputs!$E$70) -> 120.0745
B40: Delivery Service | D40: =D$14*IF(YEAR(D$8)=2023,Inputs!$D$75,Inputs!$E$75) -> 97.85 | E40: =E$14*IF(YEAR(E$8)=2023,Inputs!$D$75,Inputs!$E$75) -> 99.91 | F40: =F$14*IF(YEAR(F$8)=2023,Inputs!$D$75,Inputs!$E$75) -> 101.97 | G40: =G$14*IF(YEAR(G$8)=2023,Inputs!$D$75,Inputs!$E$75) -> 104.03 | H40: =H$14*IF(YEAR(H$8)=2023,Inputs!$D$75,Inputs!$E$75) -> 106.09 | I40: =I$14*IF(YEAR(I$8)=2023,Inputs!$D$75,Inputs!$E$75) -> 108.15 | J40: =J$14*IF(YEAR(J$8)=2023,Inputs!$D$75,Inputs!$E$75) -> 110.21 | K40: =K$14*IF(YEAR(K$8)=2023,Inputs!$D$75,Inputs!$E$75) -> 112.27 | ... AA40: =AA$14*IF(YEAR(AA$8)=2023,Inputs!$D$75,Inputs!$E$75) -> 138.5475
B41: Central Kitchen (Commissary) | D41: =D$14*IF(YEAR(D$8)=2023,Inputs!$D$80,Inputs!$E$80) -> 0 | E41: =E$14*IF(YEAR(E$8)=2023,Inputs!$D$80,Inputs!$E$80) -> 0 | F41: =F$14*IF(YEAR(F$8)=2023,Inputs!$D$80,Inputs!$E$80) -> 0 | G41: =G$14*IF(YEAR(G$8)=2023,Inputs!$D$80,Inputs!$E$80) -> 0 | H41: =H$14*IF(YEAR(H$8)=2023,Inputs!$D$80,Inputs!$E$80) -> 0 | I41: =I$14*IF(YEAR(I$8)=2023,Inputs!$D$80,Inputs!$E$80) -> 0 | J41: =J$14*IF(YEAR(J$8)=2023,Inputs!$D$80,Inputs!$E$80) -> 0 | K41: =K$14*IF(YEAR(K$8)=2023,Inputs!$D$80,Inputs!$E$80) -> 0 | ... AA41: =AA$14*IF(YEAR(AA$8)=2023,Inputs!$D$80,Inputs!$E$80) -> 0
B42: Total Revenue | D42: =SUM(D35:D41) -> 978.5 | E42: =SUM(E35:E41) -> 999.1 | F42: =SUM(F35:F41) -> 1019.7 | G42: =SUM(G35:G41) -> 1040.3 | H42: =SUM(H35:H41) -> 1060.9 | I42: =SUM(I35:I41) -> 1081.5 | J42: =SUM(J35:J41) -> 1102.1 | K42: =SUM(K35:K41) -> 1122.7 | ... AA42: =SUM(AA35:AA41) -> 923.65
B44: COGS by Segment
B46: Italian Restaurant | D46: =D$15*(IF(YEAR(D$8)=2023,Inputs!$D$91,Inputs!$E$91)) -> -158.517 | E46: =E$15*(IF(YEAR(E$8)=2023,Inputs!$D$91,Inputs!$E$91)) -> -161.8542 | F46: =F$15*(IF(YEAR(F$8)=2023,Inputs!$D$91,Inputs!$E$91)) -> -165.1914 | G46: =G$15*(IF(YEAR(G$8)=2023,Inputs!$D$91,Inputs!$E$91)) -> -168.5286 | H46: =H$15*(IF(YEAR(H$8)=2023,Inputs!$D$91,Inputs!$E$91)) -> -171.8658 | I46: =I$15*(IF(YEAR(I$8)=2023,Inputs!$D$91,Inputs!$E$91)) -> -175.203 | J46: =J$15*(IF(YEAR(J$8)=2023,Inputs!$D$91,Inputs!$E$91)) -> -178.5402 | K46: =K$15*(IF(YEAR(K$8)=2023,Inputs!$D$91,Inputs!$E$91)) -> -181.8774 | ... AA46: =AA$15*(IF(YEAR(AA$8)=2023,Inputs!$D$91,Inputs!$E$91)) -> -138.5475
B47: Japanese Restaurant | D47: =D$15*(IF(YEAR(D$8)=2023,Inputs!$D$96,Inputs!$E$96)) -> -117.42 | E47: =E$15*(IF(YEAR(E$8)=2023,Inputs!$D$96,Inputs!$E$96)) -> -119.892 | F47: =F$15*(IF(YEAR(F$8)=2023,Inputs!$D$96,Inputs!$E$96)) -> -122.364 | G47: =G$15*(IF(YEAR(G$8)=2023,Inputs!$D$96,Inputs!$E$96)) -> -124.836 | H47: =H$15*(IF(YEAR(H$8)=2023,Inputs!$D$96,Inputs!$E$96)) -> -127.308 | I47: =I$15*(IF(YEAR(I$8)=2023,Inputs!$D$96,Inputs!$E$96)) -> -129.78 | J47: =J$15*(IF(YEAR(J$8)=2023,Inputs!$D$96,Inputs!$E$96)) -> -132.252 | K47: =K$15*(IF(YEAR(K$8)=2023,Inputs!$D$96,Inputs!$E$96)) -> -134.724 | ... AA47: =AA$15*(IF(YEAR(AA$8)=2023,Inputs!$D$96,Inputs!$E$96)) -> -99.7542
B48: Burger Joint | D48: =D$15*(IF(YEAR(D$8)=2023,Inputs!$D$101,Inputs!$E$101)) -> -105.678 | E48: =E$15*(IF(YEAR(E$8)=2023,Inputs!$D$101,Inputs!$E$101)) -> -107.9028 | F48: =F$15*(IF(YEAR(F$8)=2023,Inputs!$D$101,Inputs!$E$101)) -> -110.1276 | G48: =G$15*(IF(YEAR(G$8)=2023,Inputs!$D$101,Inputs!$E$101)) -> -112.3524 | H48: =H$15*(IF(YEAR(H$8)=2023,Inputs!$D$101,Inputs!$E$101)) -> -114.5772 | I48: =I$15*(IF(YEAR(I$8)=2023,Inputs!$D$101,Inputs!$E$101)) -> -116.802 | J48: =J$15*(IF(YEAR(J$8)=2023,Inputs!$D$101,Inputs!$E$101)) -> -119.0268 | K48: =K$15*(IF(YEAR(K$8)=2023,Inputs!$D$101,Inputs!$E$101)) -> -121.2516 | ... AA48: =AA$15*(IF(YEAR(AA$8)=2023,Inputs!$D$101,Inputs!$E$101)) -> -110.838
B49: Pizzeria | D49: =D$15*(IF(YEAR(D$8)=2023,Inputs!$D$106,Inputs!$E$106)) -> -82.194 | E49: =E$15*(IF(YEAR(E$8)=2023,Inputs!$D$106,Inputs!$E$106)) -> -83.9244 | F49: =F$15*(IF(YEAR(F$8)=2023,Inputs!$D$106,Inputs!$E$106)) -> -85.6548 | G49: =G$15*(IF(YEAR(G$8)=2023,Inputs!$D$106,Inputs!$E$106)) -> -87.3852 | H49: =H$15*(IF(YEAR(H$8)=2023,Inputs!$D$106,Inputs!$E$106)) -> -89.1156 | I49: =I$15*(IF(YEAR(I$8)=2023,Inputs!$D$106,Inputs!$E$106)) -> -90.846 | J49: =J$15*(IF(YEAR(J$8)=2023,Inputs!$D$106,Inputs!$E$106)) -> -92.5764 | K49: =K$15*(IF(YEAR(K$8)=2023,Inputs!$D$106,Inputs!$E$106)) -> -94.3068 | ... AA49: =AA$15*(IF(YEAR(AA$8)=2023,Inputs!$D$106,Inputs!$E$106)) -> -77.5866
B50: Beverage Brand | D50: =D$15*(IF(YEAR(D$8)=2023,Inputs!$D$111,Inputs!$E$111)) -> -52.839 | E50: =E$15*(IF(YEAR(E$8)=2023,Inputs!$D$111,Inputs!$E$111)) -> -53.9514 | F50: =F$15*(IF(YEAR(F$8)=2023,Inputs!$D$111,Inputs!$E$111)) -> -55.0638 | G50: =G$15*(IF(YEAR(G$8)=2023,Inputs!$D$111,Inputs!$E$111)) -> -56.1762 | H50: =H$15*(IF(YEAR(H$8)=2023,Inputs!$D$111,Inputs!$E$111)) -> -57.2886 | I50: =I$15*(IF(YEAR(I$8)=2023,Inputs!$D$111,Inputs!$E$111)) -> -58.401 | J50: =J$15*(IF(YEAR(J$8)=2023,Inputs!$D$111,Inputs!$E$111)) -> -59.5134 | K50: =K$15*(IF(YEAR(K$8)=2023,Inputs!$D$111,Inputs!$E$111)) -> -60.6258 | ... AA50: =AA$15*(IF(YEAR(AA$8)=2023,Inputs!$D$111,Inputs!$E$111)) -> -44.3352
B51: Delivery Service | D51: =D$15*(IF(YEAR(D$8)=2023,Inputs!$D$116,Inputs!$E$116)) -> -52.839 | E51: =E$15*(IF(YEAR(E$8)=2023,Inputs!$D$116,Inputs!$E$116)) -> -53.9514 | F51: =F$15*(IF(YEAR(F$8)=2023,Inputs!$D$116,Inputs!$E$116)) -> -55.0638 | G51: =G$15*(IF(YEAR(G$8)=2023,Inputs!$D$116,Inputs!$E$116)) -> -56.1762 | H51: =H$15*(IF(YEAR(H$8)=2023,Inputs!$D$116,Inputs!$E$116)) -> -57.2886 | I51: =I$15*(IF(YEAR(I$8)=2023,Inputs!$D$116,Inputs!$E$116)) -> -58.401 | J51: =J$15*(IF(YEAR(J$8)=2023,Inputs!$D$116,Inputs!$E$116)) -> -59.5134 | K51: =K$15*(IF(YEAR(K$8)=2023,Inputs!$D$116,Inputs!$E$116)) -> -60.6258 | ... AA51: =AA$15*(IF(YEAR(AA$8)=2023,Inputs!$D$116,Inputs!$E$116)) -> -66.5028
B52: Central Kitchen (Commissary) | D52: =D$15*(IF(YEAR(D$8)=2023,Inputs!$D$121,Inputs!$E$121)) -> -17.613 | E52: =E$15*(IF(YEAR(E$8)=2023,Inputs!$D$121,Inputs!$E$121)) -> -17.9838 | F52: =F$15*(IF(YEAR(F$8)=2023,Inputs!$D$121,Inputs!$E$121)) -> -18.3546 | G52: =G$15*(IF(YEAR(G$8)=2023,Inputs!$D$121,Inputs!$E$121)) -> -18.7254 | H52: =H$15*(IF(YEAR(H$8)=2023,Inputs!$D$121,Inputs!$E$121)) -> -19.0962 | I52: =I$15*(IF(YEAR(I$8)=2023,Inputs!$D$121,Inputs!$E$121)) -> -19.467 | J52: =J$15*(IF(YEAR(J$8)=2023,Inputs!$D$121,Inputs!$E$121)) -> -19.8378 | K52: =K$15*(IF(YEAR(K$8)=2023,Inputs!$D$121,Inputs!$E$121)) -> -20.2086 | ... AA52: =AA$15*(IF(YEAR(AA$8)=2023,Inputs!$D$121,Inputs!$E$121)) -> -16.6257
B53: Total COGS | D53: =SUM(D46:D52) -> -587.1 | E53: =SUM(E46:E52) -> -599.46 | F53: =SUM(F46:F52) -> -611.82 | G53: =SUM(G46:G52) -> -624.18 | H53: =SUM(H46:H52) -> -636.54 | I53: =SUM(I46:I52) -> -648.9 | J53: =SUM(J46:J52) -> -661.26 | K53: =SUM(K46:K52) -> -673.62 | ... AA53: =SUM(AA46:AA52) -> -554.19
B55: Gross Profit by Segment
B57: Italian Restaurant | D57: =D35+D46 -> 86.108 | E57: =E35+E46 -> 87.9208 | F57: =F35+F46 -> 89.7336 | G57: =G35+G46 -> 91.5464 | H57: =H35+H46 -> 93.3592 | I57: =I35+I46 -> 95.172 | J57: =J35+J46 -> 96.9848 | K57: =K35+K46 -> 98.7976 | ... AA57: =AA35+AA46 -> 64.6555
B58: Japanese Restaurant | D58: =D36+D47 -> 78.28 | E58: =E36+E47 -> 79.928 | F58: =F36+F47 -> 81.576 | G58: =G36+G47 -> 83.224 | H58: =H36+H47 -> 84.872 | I58: =I36+I47 -> 86.52 | J58: =J36+J47 -> 88.168 | K58: =K36+K47 -> 89.816 | ... AA58: =AA36+AA47 -> 57.2663
...
